{
    "registryname": "blood_meat_infuser",
    "localizedname": "Blood Meat Infuser",
    "color": "381216",
    "parts": [
        {
            "x": -1,
            "y": 0,
            "z": 0,
            "elements": [
                "bloodtinker:blood_bronze_block@0"
            ]
        },
        {
            "x": -1,
            "y": 0,
            "z": 1,
            "elements": [
                "casings_all"
            ]
        },
        {
            "x": 0,
            "y": 2,
            "z": 2,
            "elements": [
                "casings_all"
            ]
        },
        {
            "x": 1,
            "y": 2,
            "z": 1,
            "elements": [
                "thermalfoundation:glass_alloy@5"
            ]
        },
        {
            "x": -1,
            "y": 0,
            "z": 2,
            "elements": [
                "bloodtinker:blood_bronze_block@0"
            ]
        },
        {
            "x": 1,
            "y": 2,
            "z": 2,
            "elements": [
                "bloodtinker:blood_bronze_block@0"
            ]
        },
        {
            "x": 1,
            "y": 0,
            "z": 0,
            "elements": [
                "bloodtinker:blood_bronze_block@0"
            ]
        },
        {
            "x": 0,
            "y": 0,
            "z": 1,
            "elements": [
                "casings_all"
            ]
        },
        {
            "x": 0,
            "y": 0,
            "z": 2,
            "elements": [
                "casings_all"
            ]
        },
        {
            "x": 1,
            "y": 0,
            "z": 1,
            "elements": [
                "casings_all"
            ]
        },
        {
            "x": 1,
            "y": 0,
            "z": 2,
            "elements": [
                "bloodtinker:blood_bronze_block@0"
            ]
        },
        {
            "x": -1,
            "y": 3,
            "z": 0,
            "elements": [
                "bloodtinker:blood_bronze_block@0"
            ]
        },
        {
            "x": -1,
            "y": 3,
            "z": 1,
            "elements": [
                "thermalfoundation:glass_alloy@5"
            ]
        },
        {
            "x": 0,
            "y": 3,
            "z": 0,
            "elements": [
                "thermalfoundation:glass_alloy@5"
            ]
        },
        {
            "x": 0,
            "y": 3,
            "z": 1,
            "elements": [
                "betternether:cincinnasite_bricks_pillar@0"
            ]
        },
        {
            "x": -1,
            "y": 1,
            "z": 0,
            "elements": [
                "bloodtinker:blood_bronze_block@0"
            ]
        },
        {
            "x": -1,
            "y": 3,
            "z": 2,
            "elements": [
                "bloodtinker:blood_bronze_block@0"
            ]
        },
        {
            "x": 1,
            "y": 3,
            "z": 0,
            "elements": [
                "bloodtinker:blood_bronze_block@0"
            ]
        },
        {
            "x": -1,
            "y": 1,
            "z": 1,
            "elements": [
                "thermalfoundation:glass_alloy@5"
            ]
        },
        {
            "x": 0,
            "y": 3,
            "z": 2,
            "elements": [
                "casings_all"
            ]
        },
        {
            "x": 1,
            "y": 3,
            "z": 1,
            "elements": [
                "thermalfoundation:glass_alloy@5"
            ]
        },
        {
            "x": 0,
            "y": 1,
            "z": 0,
            "elements": [
                "thermalfoundation:glass_alloy@5",
                "modularmachinery:blockparallelcontroller"
            ]
        },
        {
            "x": 0,
            "y": 1,
            "z": 1,
            "elements": [
                "betternether:cincinnasite_bricks_pillar@0"
            ]
        },
        {
            "x": -1,
            "y": 1,
            "z": 2,
            "elements": [
                "bloodtinker:blood_bronze_block@0"
            ]
        },
        {
            "x": 1,
            "y": 3,
            "z": 2,
            "elements": [
                "bloodtinker:blood_bronze_block@0"
            ]
        },
        {
            "x": 1,
            "y": 1,
            "z": 0,
            "elements": [
                "bloodtinker:blood_bronze_block@0"
            ]
        },
        {
            "x": 0,
            "y": 1,
            "z": 2,
            "elements": [
                "casings_all"
            ]
        },
        {
            "x": 1,
            "y": 1,
            "z": 1,
            "elements": [
                "thermalfoundation:glass_alloy@5"
            ]
        },
        {
            "x": 1,
            "y": 1,
            "z": 2,
            "elements": [
                "bloodtinker:blood_bronze_block@0"
            ]
        },
        {
            "x": -1,
            "y": 4,
            "z": 0,
            "elements": [
                "bloodtinker:blood_bronze_block@0"
            ]
        },
        {
            "x": -1,
            "y": 4,
            "z": 1,
            "elements": [
                "casings_all"
            ]
        },
        {
            "x": 0,
            "y": 4,
            "z": 0,
            "elements": [
                "modularmachinery:blockgridproviderinput@0"
            ]
        },
        {
            "x": -1,
            "y": 2,
            "z": 0,
            "elements": [
                "bloodtinker:blood_bronze_block@0"
            ]
        },
        {
            "x": -1,
            "y": 4,
            "z": 2,
            "elements": [
                "bloodtinker:blood_bronze_block@0"
            ]
        },
        {
            "x": 1,
            "y": 4,
            "z": 0,
            "elements": [
                "bloodtinker:blood_bronze_block@0"
            ]
        },
        {
            "x": 0,
            "y": 4,
            "z": 1,
            "elements": [
                "casings_all"
            ]
        },
        {
            "x": -1,
            "y": 2,
            "z": 1,
            "elements": [
                "thermalfoundation:glass_alloy@5"
            ]
        },
        {
            "x": 0,
            "y": 4,
            "z": 2,
            "elements": [
                "casings_all"
            ]
        },
        {
            "x": 1,
            "y": 4,
            "z": 1,
            "elements": [
                "casings_all"
            ]
        },
        {
            "x": 0,
            "y": 2,
            "z": 0,
            "elements": [
                "thermalfoundation:glass_alloy@5"
            ]
        },
        {
            "x": 0,
            "y": 2,
            "z": 1,
            "elements": [
                "betternether:cincinnasite_bricks_pillar@0"
            ]
        },
        {
            "x": -1,
            "y": 2,
            "z": 2,
            "elements": [
                "bloodtinker:blood_bronze_block@0"
            ]
        },
        {
            "x": 1,
            "y": 4,
            "z": 2,
            "elements": [
                "bloodtinker:blood_bronze_block@0"
            ]
        },
        {
            "x": 1,
            "y": 2,
            "z": 0,
            "elements": [
                "bloodtinker:blood_bronze_block@0"
            ]
        }
    ]}