{
    "registryname": "large_cobblegen",
    "localizedname": "Large Cobblestone Generator",
    "color": "242530",
    "modifiers": [
        {"description": "halves recipe time",
            "x": 1,
            "y": 1,
            "z": 0,
            "elements": [
                "contenttweaker:rune_fire_block@0"
            ],
            "modifier": [
                {
                    "io": "input",
                    "target": "duration",
                    "operation": 1,
                    "multiplier": 0.5
                }
            ]
        },
        {
            "x": -1,
            "y": 1,
            "z": 2,
            "elements": [
                "contenttweaker:rune_fire_block@0"
            ],
            "modifier": [
                {
                    "io": "input",
                    "target": "duration",
                    "operation": 1,
                    "multiplier": 0.5
                }
            ]
        },

        {"description": "halves input fluids and items",
            "x": 1,
            "y": 1,
            "z": 2,
            "elements": [
                "contenttweaker:rune_water_block@0"
            ],
            "modifier": [
                {
                    "io": "input",
                    "target": "item",
                    "operation": 1,
                    "multiplier": 0.5
                },
                {
                    "io": "input",
                    "target": "fluid",
                    "operation": 1,
                    "multiplier": 0.5
                }
            ]
        },
        {
            "x": -1,
            "y": 1,
            "z": 0,
            "elements": [
                "contenttweaker:rune_water_block@0"
            ],
            "modifier": [
                {
                    "io": "input",
                    "target": "item",
                    "operation": 1,
                    "multiplier": 0.5
                },
                {
                    "io": "input",
                    "target": "fluid",
                    "operation": 1,
                    "multiplier": 0.5
                }
            ]
        },

        {"description": "+1 output item",
            "x": 0,
            "y": 1,
            "z": 1,
            "elements": [
                "minecraft:bedrock@0"
            ],
            "modifier":
            {
                "io": "output",
                "target": "item",
                "operation": 0,
                "multiplier": 1
            }
        },

        {"description": "+1 output item",
            "x": 0,
            "y": 1,
            "z": 2,
            "elements": [
                "contenttweaker:neutronium_sheetmetal@0"
            ],
            "modifier":
            {
                "io": "output",
                "target": "item",
                "operation": 0,
                "multiplier": 1
            }
        },
        {
            "x": 1,
            "y": 1,
            "z": 1,
            "elements": [
                "contenttweaker:neutronium_sheetmetal@0"
            ],
            "modifier":
            {
                "io": "output",
                "target": "item",
                "operation": 0,
                "multiplier": 1
            }
        },
        {
            "x": -1,
            "y": 1,
            "z": 1,
            "elements": [
                "contenttweaker:neutronium_sheetmetal@0"
            ],
            "modifier":
            {
                "io": "output",
                "target": "item",
                "operation": 0,
                "multiplier": 1
            }
        },
        {
            "x": 0,
            "y": 1,
            "z": 0,
            "elements": [
                "contenttweaker:neutronium_sheetmetal@0"
            ],
            "modifier":
            {
                "io": "output",
                "target": "item",
                "operation": 0,
                "multiplier": 1
            }
        }
    ],
    "parts": [
        {
            "x": -1,
            "y": 0,
            "z": 0,
            "elements": [
                "casings_all"
            ]
        },
        {
            "x": -1,
            "y": 0,
            "z": 1,
            "elements": [
                "casings_all"
            ]
        },
        {
            "x": 0,
            "y": 2,
            "z": 2,
            "elements": [
                "casings_all"
            ]
        },
        {
            "x": 1,
            "y": 2,
            "z": 1,
            "elements": [
                "casings_all"
            ]
        },
        {
            "x": 0,
            "y": 0,
            "z": 1,
            "elements": [
                "casings_all"
            ]
        },
        {
            "x": 1,
            "y": 0,
            "z": 0,
            "elements": [
                "casings_all"
            ]
        },
        {
            "x": -1,
            "y": 0,
            "z": 2,
            "elements": [
                "casings_all"
            ]
        },
        {
            "x": 1,
            "y": 2,
            "z": 2,
            "elements": [
                "casings_all"
            ]
        },
        {
            "x": 1,
            "y": 0,
            "z": 1,
            "elements": [
                "casings_all"
            ]
        },
        {
            "x": 0,
            "y": 0,
            "z": 2,
            "elements": [
                "casings_all"
            ]
        },
        {
            "x": 1,
            "y": 0,
            "z": 2,
            "elements": [
                "casings_all"
            ]
        },
        {
            "x": -1,
            "y": 1,
            "z": 0,
            "elements": [
                "chisel:waterstone1@1"
            ]
        },
        {
            "x": 0,
            "y": 1,
            "z": 0,
            "elements": [
                "immersiveengineering:stone_decoration@7"
            ]
        },
        {
            "x": -1,
            "y": 1,
            "z": 1,
            "elements": [
                "immersiveengineering:stone_decoration@7"
            ]
        },
        {
            "x": 0,
            "y": 1,
            "z": 1,
            "elements": [
                "contenttweaker:bedrockium_alloy_block@0"
            ]
        },
        {
            "x": 1,
            "y": 1,
            "z": 0,
            "elements": [
                "chisel:lavastone1@1"
            ]
        },
        {
            "x": -1,
            "y": 1,
            "z": 2,
            "elements": [
                "chisel:lavastone1@1"
            ]
        },
        {
            "x": 0,
            "y": 1,
            "z": 2,
            "elements": [
                "immersiveengineering:stone_decoration@7"
            ]
        },
        {
            "x": 1,
            "y": 1,
            "z": 1,
            "elements": [
                "immersiveengineering:stone_decoration@7"
            ]
        },
        {
            "x": 1,
            "y": 1,
            "z": 2,
            "elements": [
                "chisel:waterstone1@1"
            ]
        },
        {
            "x": -1,
            "y": 2,
            "z": 0,
            "elements": [
                "casings_all"
            ]
        },
        {
            "x": -1,
            "y": 2,
            "z": 1,
            "elements": [
                "casings_all"
            ]
        },
        {
            "x": 0,
            "y": 2,
            "z": 0,
            "elements": [
                "casings_all"
            ]
        },
        {
            "x": -1,
            "y": 2,
            "z": 2,
            "elements": [
                "casings_all"
            ]
        },
        {
            "x": 0,
            "y": 2,
            "z": 1,
            "elements": [
                "casings_all"
            ]
        },
        {
            "x": 1,
            "y": 2,
            "z": 0,
            "elements": [
                "casings_all"
            ]
        }
    ]}