{
    "registryname": "large_sifter",
    "localizedname": "Large Sifter",
    "color": "242530",
    "modifiers": [
        {
            "x": -1,
            "y": 1,
            "z": 2,
            "elements": [
                "contenttweaker:lucky_gearbox@0"
            ],
            "modifier": [
                {
                    "io": "output",
                    "target": "item",
                    "operation": 0,
                    "multiplier": 8
                }, {
                    "io": "input",
                    "target": "fluid",
                    "operation": 0,
                    "multiplier": 50
                }, {
                    "io": "input",
                    "target": "energy",
                    "operation": 1,
                    "multiplier": 1.5
                }
            ],
            "description": "+8 item output, +50 fluid input, x1.5 energy input"
        },
        {
            "x": -1,
            "y": 2,
            "z": 3,
            "elements": [
                "contenttweaker:lucky_gearbox@0"
            ],
            "modifier": [
                {
                    "io": "output",
                    "target": "item",
                    "operation": 0,
                    "multiplier": 8
                }, {
                    "io": "input",
                    "target": "duration",
                    "operation": 0,
                    "multiplier": 50
                }, {
                    "io": "input",
                    "target": "energy",
                    "operation": 1,
                    "multiplier": 1.5
                }
            ]
        },
        {
            "x": 0,
            "y": 2,
            "z": 2,
            "elements": [
                "contenttweaker:lucky_gearbox@0"
            ],
            "modifier": [
                {
                    "io": "output",
                    "target": "item",
                    "operation": 0,
                    "multiplier": 8
                }, {
                    "io": "input",
                    "target": "fluid",
                    "operation": 0,
                    "multiplier": 50
                }, {
                    "io": "input",
                    "target": "energy",
                    "operation": 1,
                    "multiplier": 1.5
                }
            ]
        },
        {
            "x": 0,
            "y": 1,
            "z": 1,
            "elements": [
                "contenttweaker:lucky_gearbox@0"
            ],
            "modifier": [
                {
                    "io": "output",
                    "target": "item",
                    "operation": 0,
                    "multiplier": 8
                }, {
                    "io": "input",
                    "target": "fluid",
                    "operation": 0,
                    "multiplier": 50
                }, {
                    "io": "input",
                    "target": "energy",
                    "operation": 1,
                    "multiplier": 1.5
                }
            ]
        },
        {
            "x": 1,
            "y": 2,
            "z": 1,
            "elements": [
                "contenttweaker:lucky_gearbox@0"
            ],
            "modifier": [
                {
                    "io": "output",
                    "target": "item",
                    "operation": 0,
                    "multiplier": 8
                }, {
                    "io": "input",
                    "target": "fluid",
                    "operation": 0,
                    "multiplier": 50
                }, {
                    "io": "input",
                    "target": "energy",
                    "operation": 1,
                    "multiplier": 1.5
                }
            ]
        },
        {
            "x": -1,
            "y": 1,
            "z": 3,
            "elements": [
                "contenttweaker:lucky_gearbox@0"
            ],
            "modifier": [
                {
                    "io": "output",
                    "target": "item",
                    "operation": 0,
                    "multiplier": 8
                }, {
                    "io": "input",
                    "target": "fluid",
                    "operation": 0,
                    "multiplier": 50
                }, {
                    "io": "input",
                    "target": "energy",
                    "operation": 1,
                    "multiplier": 1.5
                }
            ]
        },
        {
            "x": 0,
            "y": 2,
            "z": 3,
            "elements": [
                "contenttweaker:lucky_gearbox@0"
            ],
            "modifier": [
                {
                    "io": "output",
                    "target": "item",
                    "operation": 0,
                    "multiplier": 8
                }, {
                    "io": "input",
                    "target": "fluid",
                    "operation": 0,
                    "multiplier": 50
                }, {
                    "io": "input",
                    "target": "energy",
                    "operation": 1,
                    "multiplier": 1.5
                }
            ]
        },
        {
            "x": 0,
            "y": 1,
            "z": 2,
            "elements": [
                "contenttweaker:lucky_gearbox@0"
            ],
            "modifier": [
                {
                    "io": "output",
                    "target": "item",
                    "operation": 0,
                    "multiplier": 8
                }, {
                    "io": "input",
                    "target": "fluid",
                    "operation": 0,
                    "multiplier": 50
                }, {
                    "io": "input",
                    "target": "energy",
                    "operation": 1,
                    "multiplier": 1.5
                }
            ]
        },
        {
            "x": 1,
            "y": 2,
            "z": 2,
            "elements": [
                "contenttweaker:lucky_gearbox@0"
            ],
            "modifier": [
                {
                    "io": "output",
                    "target": "item",
                    "operation": 0,
                    "multiplier": 8
                }, {
                    "io": "input",
                    "target": "fluid",
                    "operation": 0,
                    "multiplier": 50
                }, {
                    "io": "input",
                    "target": "energy",
                    "operation": 1,
                    "multiplier": 1.5
                }
            ]
        },
        {
            "x": 1,
            "y": 1,
            "z": 1,
            "elements": [
                "contenttweaker:lucky_gearbox@0"
            ],
            "modifier": [
                {
                    "io": "output",
                    "target": "item",
                    "operation": 0,
                    "multiplier": 8
                }, {
                    "io": "input",
                    "target": "fluid",
                    "operation": 0,
                    "multiplier": 50
                }, {
                    "io": "input",
                    "target": "energy",
                    "operation": 1,
                    "multiplier": 1.5
                }
            ]
        },
        {
            "x": 0,
            "y": 1,
            "z": 3,
            "elements": [
                "contenttweaker:lucky_gearbox@0"
            ],
            "modifier": [
                {
                    "io": "output",
                    "target": "item",
                    "operation": 0,
                    "multiplier": 8
                }, {
                    "io": "input",
                    "target": "fluid",
                    "operation": 0,
                    "multiplier": 50
                }, {
                    "io": "input",
                    "target": "energy",
                    "operation": 1,
                    "multiplier": 1.5
                }
            ]
        },
        {
            "x": 1,
            "y": 2,
            "z": 3,
            "elements": [
                "contenttweaker:lucky_gearbox@0"
            ],
            "modifier": [
                {
                    "io": "output",
                    "target": "item",
                    "operation": 0,
                    "multiplier": 8
                }, {
                    "io": "input",
                    "target": "fluid",
                    "operation": 0,
                    "multiplier": 50
                }, {
                    "io": "input",
                    "target": "energy",
                    "operation": 1,
                    "multiplier": 1.5
                }
            ]
        },
        {
            "x": 1,
            "y": 1,
            "z": 2,
            "elements": [
                "contenttweaker:lucky_gearbox@0"
            ],
            "modifier": [
                {
                    "io": "output",
                    "target": "item",
                    "operation": 0,
                    "multiplier": 8
                }, {
                    "io": "input",
                    "target": "fluid",
                    "operation": 0,
                    "multiplier": 50
                }, {
                    "io": "input",
                    "target": "energy",
                    "operation": 1,
                    "multiplier": 1.5
                }
            ]
        },
        {
            "x": 1,
            "y": 1,
            "z": 3,
            "elements": [
                "contenttweaker:lucky_gearbox@0"
            ],
            "modifier": [
                {
                    "io": "output",
                    "target": "item",
                    "operation": 0,
                    "multiplier": 8
                }, {
                    "io": "input",
                    "target": "fluid",
                    "operation": 0,
                    "multiplier": 50
                }, {
                    "io": "input",
                    "target": "energy",
                    "operation": 1,
                    "multiplier": 1.5
                }
            ]
        },
        {
            "x": -1,
            "y": 2,
            "z": 1,
            "elements": [
                "contenttweaker:lucky_gearbox@0"
            ],
            "modifier": [
                {
                    "io": "output",
                    "target": "item",
                    "operation": 0,
                    "multiplier": 8
                }, {
                    "io": "input",
                    "target": "fluid",
                    "operation": 0,
                    "multiplier": 50
                }, {
                    "io": "input",
                    "target": "energy",
                    "operation": 1,
                    "multiplier": 1.5
                }
            ]
        },
        {
            "x": -1,
            "y": 1,
            "z": 1,
            "elements": [
                "contenttweaker:lucky_gearbox@0"
            ],
            "modifier": [
                {
                    "io": "output",
                    "target": "item",
                    "operation": 0,
                    "multiplier": 8
                }, {
                    "io": "input",
                    "target": "fluid",
                    "operation": 0,
                    "multiplier": 50
                }, {
                    "io": "input",
                    "target": "energy",
                    "operation": 1,
                    "multiplier": 1.5
                }
            ]
        },
        {
            "x": -1,
            "y": 2,
            "z": 2,
            "elements": [
                "contenttweaker:lucky_gearbox@0"
            ],
            "modifier": [
                {
                    "io": "output",
                    "target": "item",
                    "operation": 0,
                    "multiplier": 8
                }, {
                    "io": "input",
                    "target": "fluid",
                    "operation": 0,
                    "multiplier": 50
                }, {
                    "io": "input",
                    "target": "energy",
                    "operation": 1,
                    "multiplier": 1.5
                }
            ]
        },
        {
            "x": 0,
            "y": 2,
            "z": 1,
            "elements": [
                "contenttweaker:lucky_gearbox@0"
            ],
            "modifier": [
                {
                    "io": "output",
                    "target": "item",
                    "operation": 0,
                    "multiplier": 8
                }, {
                    "io": "input",
                    "target": "fluid",
                    "operation": 0,
                    "multiplier": 50
                }, {
                    "io": "input",
                    "target": "energy",
                    "operation": 1,
                    "multiplier": 1.5
                }
            ]
        }
    ],
    "parts": [
        {
            "x": 1,
            "y": 2,
            "z": 1,
            "elements": [
                "chisel:ironpane@12"
            ]
        },
        {
            "x": -1,
            "y": 2,
            "z": 3,
            "elements": [
                "chisel:ironpane@12"
            ]
        },
        {
            "x": -2,
            "y": 0,
            "z": 2,
            "elements": [
                "casings_all",
                "immersiveengineering:storage@2"
            ]
        },
        {
            "x": -1,
            "y": 0,
            "z": 0,
            "elements": [
                "casings_all",
                "immersiveengineering:storage@2"
            ]
        },
        {
            "x": 2,
            "y": 2,
            "z": 1,
            "elements": [
                "thermalfoundation:glass_alloy@7"
            ]
        },
        {
            "x": 0,
            "y": 2,
            "z": 3,
            "elements": [
                "chisel:ironpane@12"
            ]
        },
        {
            "x": 1,
            "y": 0,
            "z": 0,
            "elements": [
                "casings_all",
                "immersiveengineering:storage@2"
            ]
        },
        {
            "x": -1,
            "y": 0,
            "z": 2,
            "elements": [
                "chisel:technical@13"
            ]
        },
        {
            "x": 1,
            "y": 2,
            "z": 3,
            "elements": [
                "chisel:ironpane@12"
            ]
        },
        {
            "x": 0,
            "y": 0,
            "z": 2,
            "elements": [
                "chisel:technical@13"
            ]
        },
        {
            "x": 2,
            "y": 2,
            "z": 3,
            "elements": [
                "thermalfoundation:glass_alloy@7"
            ]
        },
        {
            "x": 1,
            "y": 0,
            "z": 2,
            "elements": [
                "chisel:technical@13"
            ]
        },
        {
            "x": -1,
            "y": 0,
            "z": 4,
            "elements": [
                "casings_all",
                "immersiveengineering:storage@2"
            ]
        },
        {
            "x": 2,
            "y": 0,
            "z": 2,
            "elements": [
                "casings_all",
                "immersiveengineering:storage@2"
            ]
        },
        {
            "x": 0,
            "y": 0,
            "z": 4,
            "elements": [
                "casings_all",
                "immersiveengineering:storage@2"
            ]
        },
        {
            "x": 1,
            "y": 0,
            "z": 4,
            "elements": [
                "casings_all",
                "immersiveengineering:storage@2"
            ]
        },
        {
            "x": -2,
            "y": 3,
            "z": 1,
            "nbt": {"id":"immersiveengineering:ieslab","slabType":"0"},
            "elements": [
                "immersiveengineering:storage_slab@2"
            ]
        },
        {
            "x": -1,
            "y": 3,
            "z": 1,
            "elements": [
                "chisel:technical@13"
            ]
        },
        {
            "x": 0,
            "y": 3,
            "z": 1,
            "elements": [
                "chisel:technical@13"
            ]
        },
        {
            "x": -2,
            "y": 3,
            "z": 3,
            "nbt": {"id":"immersiveengineering:ieslab","slabType":"0"},
            "elements": [
                "immersiveengineering:storage_slab@2"
            ]
        },
        {
            "x": -1,
            "y": 1,
            "z": 0,
            "elements": [
                "thermalfoundation:glass_alloy@7"
            ]
        },
        {
            "x": 1,
            "y": 3,
            "z": 1,
            "elements": [
                "chisel:technical@13"
            ]
        },
        {
            "x": -1,
            "y": 3,
            "z": 3,
            "elements": [
                "chisel:technical@13"
            ]
        },
        {
            "x": 0,
            "y": 1,
            "z": 0,
            "elements": [
                "thermalfoundation:glass_alloy@7"
            ]
        },
        {
            "x": -2,
            "y": 1,
            "z": 2,
            "elements": [
                "modularmachinery:blockcasing@3"
            ]
        },
        {
            "x": -1,
            "y": 1,
            "z": 2,
            "elements": [
                "chisel:ironpane@12"
            ]
        },
        {
            "x": 2,
            "y": 3,
            "z": 1,
            "nbt": {"id":"immersiveengineering:ieslab","slabType":"0"},
            "elements": [
                "immersiveengineering:storage_slab@2"
            ]
        },
        {
            "x": 0,
            "y": 3,
            "z": 3,
            "elements": [
                "chisel:technical@13"
            ]
        },
        {
            "x": 1,
            "y": 1,
            "z": 0,
            "elements": [
                "thermalfoundation:glass_alloy@7"
            ]
        },
        {
            "x": 0,
            "y": 1,
            "z": 2,
            "elements": [
                "chisel:ironpane@12"
            ]
        },
        {
            "x": 1,
            "y": 3,
            "z": 3,
            "elements": [
                "chisel:technical@13"
            ]
        },
        {
            "x": 1,
            "y": 1,
            "z": 2,
            "elements": [
                "chisel:ironpane@12"
            ]
        },
        {
            "x": 2,
            "y": 3,
            "z": 3,
            "nbt": {"id":"immersiveengineering:ieslab","slabType":"0"},
            "elements": [
                "immersiveengineering:storage_slab@2"
            ]
        },
        {
            "x": -1,
            "y": 1,
            "z": 4,
            "elements": [
                "thermalfoundation:glass_alloy@7"
            ]
        },
        {
            "x": 2,
            "y": 1,
            "z": 2,
            "elements": [
                "modularmachinery:blockcasing@3"
            ]
        },
        {
            "x": 0,
            "y": 1,
            "z": 4,
            "elements": [
                "modularmachinery:blockcasing@3"
            ]
        },
        {
            "x": 1,
            "y": 1,
            "z": 4,
            "elements": [
                "thermalfoundation:glass_alloy@7"
            ]
        },
        {
            "x": -1,
            "y": 2,
            "z": 0,
            "elements": [
                "thermalfoundation:glass_alloy@7"
            ]
        },
        {
            "x": 0,
            "y": 2,
            "z": 0,
            "elements": [
                "thermalfoundation:glass_alloy@7"
            ]
        },
        {
            "x": -2,
            "y": 2,
            "z": 2,
            "elements": [
                "modularmachinery:blockcasing@3"
            ]
        },
        {
            "x": -1,
            "y": 2,
            "z": 2,
            "elements": [
                "chisel:ironpane@12"
            ]
        },
        {
            "x": 1,
            "y": 2,
            "z": 0,
            "elements": [
                "thermalfoundation:glass_alloy@7"
            ]
        },
        {
            "x": -2,
            "y": 0,
            "z": 1,
            "elements": [
                "casings_all",
                "immersiveengineering:storage@2"
            ]
        },
        {
            "x": 0,
            "y": 2,
            "z": 2,
            "elements": [
                "chisel:ironpane@12"
            ]
        },
        {
            "x": -1,
            "y": 0,
            "z": 1,
            "elements": [
                "chisel:technical@13"
            ]
        },
        {
            "x": 1,
            "y": 2,
            "z": 2,
            "elements": [
                "chisel:ironpane@12"
            ]
        },
        {
            "x": -1,
            "y": 2,
            "z": 4,
            "elements": [
                "thermalfoundation:glass_alloy@7"
            ]
        },
        {
            "x": -2,
            "y": 0,
            "z": 3,
            "elements": [
                "casings_all",
                "immersiveengineering:storage@2"
            ]
        },
        {
            "x": 0,
            "y": 0,
            "z": 1,
            "elements": [
                "chisel:technical@13"
            ]
        },
        {
            "x": 2,
            "y": 2,
            "z": 2,
            "elements": [
                "modularmachinery:blockcasing@3"
            ]
        },
        {
            "x": 0,
            "y": 2,
            "z": 4,
            "elements": [
                "modularmachinery:blockcasing@3"
            ]
        },
        {
            "x": 1,
            "y": 0,
            "z": 1,
            "elements": [
                "chisel:technical@13"
            ]
        },
        {
            "x": -1,
            "y": 0,
            "z": 3,
            "elements": [
                "chisel:technical@13"
            ]
        },
        {
            "x": 1,
            "y": 2,
            "z": 4,
            "elements": [
                "thermalfoundation:glass_alloy@7"
            ]
        },
        {
            "x": 2,
            "y": 0,
            "z": 1,
            "elements": [
                "casings_all",
                "immersiveengineering:storage@2"
            ]
        },
        {
            "x": 0,
            "y": 0,
            "z": 3,
            "elements": [
                "chisel:technical@13"
            ]
        },
        {
            "x": 1,
            "y": 0,
            "z": 3,
            "elements": [
                "chisel:technical@13"
            ]
        },
        {
            "x": 2,
            "y": 0,
            "z": 3,
            "elements": [
                "casings_all",
                "immersiveengineering:storage@2"
            ]
        },
        {
            "x": -1,
            "y": 3,
            "z": 0,
            "nbt": {"id":"immersiveengineering:ieslab","slabType":"0"},
            "elements": [
                "immersiveengineering:storage_slab@2"
            ]
        },
        {
            "x": 0,
            "y": 3,
            "z": 0,
            "nbt": {"id":"immersiveengineering:ieslab","slabType":"0"},
            "elements": [
                "immersiveengineering:storage_slab@2"
            ]
        },
        {
            "x": -2,
            "y": 3,
            "z": 2,
            "nbt": {"id":"immersiveengineering:ieslab","slabType":"0"},
            "elements": [
                "immersiveengineering:storage_slab@2"
            ]
        },
        {
            "x": 1,
            "y": 3,
            "z": 0,
            "nbt": {"id":"immersiveengineering:ieslab","slabType":"0"},
            "elements": [
                "immersiveengineering:storage_slab@2"
            ]
        },
        {
            "x": -1,
            "y": 3,
            "z": 2,
            "elements": [
                "chisel:technical@13"
            ]
        },
        {
            "x": -2,
            "y": 1,
            "z": 1,
            "elements": [
                "thermalfoundation:glass_alloy@7"
            ]
        },
        {
            "x": -1,
            "y": 1,
            "z": 1,
            "elements": [
                "chisel:ironpane@12"
            ]
        },
        {
            "x": 0,
            "y": 3,
            "z": 2,
            "elements": [
                "chisel:technical@13"
            ]
        },
        {
            "x": 0,
            "y": 1,
            "z": 1,
            "elements": [
                "chisel:ironpane@12"
            ]
        },
        {
            "x": 1,
            "y": 3,
            "z": 2,
            "elements": [
                "chisel:technical@13"
            ]
        },
        {
            "x": -1,
            "y": 3,
            "z": 4,
            "nbt": {"id":"immersiveengineering:ieslab","slabType":"0"},
            "elements": [
                "immersiveengineering:storage_slab@2"
            ]
        },
        {
            "x": -2,
            "y": 1,
            "z": 3,
            "elements": [
                "thermalfoundation:glass_alloy@7"
            ]
        },
        {
            "x": 1,
            "y": 1,
            "z": 1,
            "elements": [
                "chisel:ironpane@12"
            ]
        },
        {
            "x": -1,
            "y": 1,
            "z": 3,
            "elements": [
                "chisel:ironpane@12"
            ]
        },
        {
            "x": 2,
            "y": 3,
            "z": 2,
            "nbt": {"id":"immersiveengineering:ieslab","slabType":"0"},
            "elements": [
                "immersiveengineering:storage_slab@2"
            ]
        },
        {
            "x": 0,
            "y": 3,
            "z": 4,
            "nbt": {"id":"immersiveengineering:ieslab","slabType":"0"},
            "elements": [
                "immersiveengineering:storage_slab@2"
            ]
        },
        {
            "x": 2,
            "y": 1,
            "z": 1,
            "elements": [
                "thermalfoundation:glass_alloy@7"
            ]
        },
        {
            "x": 0,
            "y": 1,
            "z": 3,
            "elements": [
                "chisel:ironpane@12"
            ]
        },
        {
            "x": 1,
            "y": 3,
            "z": 4,
            "nbt": {"id":"immersiveengineering:ieslab","slabType":"0"},
            "elements": [
                "immersiveengineering:storage_slab@2"
            ]
        },
        {
            "x": 1,
            "y": 1,
            "z": 3,
            "elements": [
                "chisel:ironpane@12"
            ]
        },
        {
            "x": 2,
            "y": 1,
            "z": 3,
            "elements": [
                "thermalfoundation:glass_alloy@7"
            ]
        },
        {
            "x": -2,
            "y": 2,
            "z": 1,
            "elements": [
                "thermalfoundation:glass_alloy@7"
            ]
        },
        {
            "x": -1,
            "y": 2,
            "z": 1,
            "elements": [
                "chisel:ironpane@12"
            ]
        },
        {
            "x": 0,
            "y": 2,
            "z": 1,
            "elements": [
                "chisel:ironpane@12"
            ]
        },
        {
            "x": -2,
            "y": 2,
            "z": 3,
            "elements": [
                "thermalfoundation:glass_alloy@7"
            ]
        }
    ]}