{
    "registryname": "super_mixer",
    "localizedname": "Supreme Mixer",
    "color": "464645",
    "parts": [
        {
            "x": 1,
            "y": 5,
            "z": 4,
            "elements": [
                "engineersdecor:panzerglass_block@0"
            ]
        },
        {
            "x": 1,
            "y": 5,
            "z": 2,
            "elements": [
                "contenttweaker:crystal_metal_block@0"
            ]
        },
        {
            "x": 2,
            "y": 3,
            "z": 1,
            "elements": [
                "engineersdecor:panzerglass_block@0"
            ]
        },
        {
            "x": 2,
            "y": 3,
            "z": 2,
            "elements": [
                "engineersdecor:panzerglass_block@0"
            ]
        },
        {
            "x": 2,
            "y": 3,
            "z": 3,
            "elements": [
                "engineersdecor:panzerglass_block@0"
            ]
        },
        {
            "x": -1,
            "y": 6,
            "z": 4,
            "elements": [
                "casings_all",
                "modularmachinery:blockwillproviderinput@0",
                "modularmachinery:blockgridproviderinput@0",
                "modularmachinery:blockmanainputhatch@0",
                
                
                "modularmachinery:blocklifeessenceproviderinput@0"
            ]
        },
        {
            "x": 0,
            "y": 4,
            "z": 0,
            "elements": [
                "engineersdecor:panzerglass_block@0"
            ]
        },
        {
            "x": -1,
            "y": 6,
            "z": 2,
            "elements": [
                "casings_all",
                "modularmachinery:blockwillproviderinput@0",
                "modularmachinery:blockgridproviderinput@0",
                "modularmachinery:blockmanainputhatch@0",
                
                
                "modularmachinery:blocklifeessenceproviderinput@0"
            ]
        },
        {
            "x": 0,
            "y": 4,
            "z": 2,
            "elements": [
                "contenttweaker:rotor@0"
            ]
        },
        {
            "x": -1,
            "y": 6,
            "z": 3,
            "elements": [
                "casings_all",
                "modularmachinery:blockwillproviderinput@0",
                "modularmachinery:blockgridproviderinput@0",
                "modularmachinery:blockmanainputhatch@0",
                
                
                "modularmachinery:blocklifeessenceproviderinput@0"
            ]
        },
        {
            "x": -2,
            "y": 1,
            "z": 2,
            "elements": [
                "engineersdecor:panzerglass_block@0"
            ]
        },
        {
            "x": -2,
            "y": 1,
            "z": 3,
            "elements": [
                "engineersdecor:panzerglass_block@0"
            ]
        },
        {
            "x": -2,
            "y": 1,
            "z": 1,
            "elements": [
                "engineersdecor:panzerglass_block@0"
            ]
        },
        {
            "x": 2,
            "y": 6,
            "z": 1,
            "elements": [
                "casings_all",
                "modularmachinery:blockwillproviderinput@0",
                "modularmachinery:blockgridproviderinput@0",
                "modularmachinery:blockmanainputhatch@0",
                
                
                "modularmachinery:blocklifeessenceproviderinput@0"
            ]
        },
        {
            "x": 2,
            "y": 6,
            "z": 2,
            "elements": [
                "casings_all",
                "modularmachinery:blockwillproviderinput@0",
                "modularmachinery:blockgridproviderinput@0",
                "modularmachinery:blockmanainputhatch@0",
                
                
                "modularmachinery:blocklifeessenceproviderinput@0"
            ]
        },
        {
            "x": 2,
            "y": 6,
            "z": 3,
            "elements": [
                "casings_all",
                "modularmachinery:blockwillproviderinput@0",
                "modularmachinery:blockgridproviderinput@0",
                "modularmachinery:blockmanainputhatch@0",
                
                
                "modularmachinery:blocklifeessenceproviderinput@0"
            ]
        },
        {
            "x": -1,
            "y": 6,
            "z": 0,
            "elements": [
                "casings_all",
                "modularmachinery:blockwillproviderinput@0",
                "modularmachinery:blockgridproviderinput@0",
                "modularmachinery:blockmanainputhatch@0",
                
                
                "modularmachinery:blocklifeessenceproviderinput@0"
            ]
        },
        {
            "x": 1,
            "y": 5,
            "z": 0,
            "elements": [
                "engineersdecor:panzerglass_block@0"
            ]
        },
        {
            "x": -1,
            "y": 6,
            "z": 1,
            "elements": [
                "casings_all",
                "modularmachinery:blockwillproviderinput@0",
                "modularmachinery:blockgridproviderinput@0",
                "modularmachinery:blockmanainputhatch@0",
                
                
                "modularmachinery:blocklifeessenceproviderinput@0"
            ]
        },
        {
            "x": 0,
            "y": 0,
            "z": 4,
            "elements": [
                "casings_all",
                "modularmachinery:blockwillproviderinput@0",
                "modularmachinery:blockgridproviderinput@0",
                "modularmachinery:blockmanainputhatch@0",
                
                
                "modularmachinery:blocklifeessenceproviderinput@0"
            ]
        },
        {
            "x": 0,
            "y": 0,
            "z": 3,
            "elements": [
                "casings_all",
                "modularmachinery:blockwillproviderinput@0",
                "modularmachinery:blockgridproviderinput@0",
                "modularmachinery:blockmanainputhatch@0",
                
                
                "modularmachinery:blocklifeessenceproviderinput@0"
            ]
        },
        {
            "x": 0,
            "y": 0,
            "z": 2,
            "elements": [
                "casings_all",
                "modularmachinery:blockwillproviderinput@0",
                "modularmachinery:blockgridproviderinput@0",
                "modularmachinery:blockmanainputhatch@0",
                
                
                "modularmachinery:blocklifeessenceproviderinput@0"
            ]
        },
        {
            "x": 0,
            "y": 0,
            "z": 1,
            "elements": [
                "casings_all",
                "modularmachinery:blockwillproviderinput@0",
                "modularmachinery:blockgridproviderinput@0",
                "modularmachinery:blockmanainputhatch@0",
                
                
                "modularmachinery:blocklifeessenceproviderinput@0"
            ]
        },
        {
            "x": 1,
            "y": 2,
            "z": 4,
            "elements": [
                "engineersdecor:panzerglass_block@0"
            ]
        },
        {
            "x": -1,
            "y": 3,
            "z": 4,
            "elements": [
                "engineersdecor:panzerglass_block@0"
            ]
        },
        {
            "x": -1,
            "y": 3,
            "z": 2,
            "elements": [
                "contenttweaker:crystal_metal_block@0"
            ]
        },
        {
            "x": 1,
            "y": 2,
            "z": 0,
            "elements": [
                "engineersdecor:panzerglass_block@0"
            ]
        },
        {
            "x": -1,
            "y": 3,
            "z": 0,
            "elements": [
                "engineersdecor:panzerglass_block@0"
            ]
        },
        {
            "x": -2,
            "y": 4,
            "z": 2,
            "elements": [
                "engineersdecor:panzerglass_block@0"
            ]
        },
        {
            "x": -2,
            "y": 4,
            "z": 1,
            "elements": [
                "engineersdecor:panzerglass_block@0"
            ]
        },
        {
            "x": -2,
            "y": 4,
            "z": 3,
            "elements": [
                "engineersdecor:panzerglass_block@0"
            ]
        },
        {
            "x": 0,
            "y": 3,
            "z": 1,
            "elements": [
                "contenttweaker:crystal_metal_block@0"
            ]
        },
        {
            "x": 0,
            "y": 3,
            "z": 0,
            "elements": [
                "engineersdecor:panzerglass_block@0"
            ]
        },
        {
            "x": 0,
            "y": 3,
            "z": 3,
            "elements": [
                "contenttweaker:crystal_metal_block@0"
            ]
        },
        {
            "x": 0,
            "y": 3,
            "z": 2,
            "elements": [
                "contenttweaker:rotor@0"
            ]
        },
        {
            "x": 1,
            "y": 1,
            "z": 0,
            "elements": [
                "engineersdecor:panzerglass_block@0"
            ]
        },
        {
            "x": 0,
            "y": 3,
            "z": 4,
            "elements": [
                "engineersdecor:panzerglass_block@0"
            ]
        },
        {
            "x": 1,
            "y": 1,
            "z": 4,
            "elements": [
                "engineersdecor:panzerglass_block@0"
            ]
        },
        {
            "x": 1,
            "y": 1,
            "z": 2,
            "elements": [
                "contenttweaker:crystal_metal_block@0"
            ]
        },
        {
            "x": 0,
            "y": 5,
            "z": 2,
            "elements": [
                "contenttweaker:rotor@0"
            ]
        },
        {
            "x": -2,
            "y": 5,
            "z": 1,
            "elements": [
                "engineersdecor:panzerglass_block@0"
            ]
        },
        {
            "x": 0,
            "y": 5,
            "z": 3,
            "elements": [
                "contenttweaker:crystal_metal_block@0"
            ]
        },
        {
            "x": 0,
            "y": 5,
            "z": 4,
            "elements": [
                "engineersdecor:panzerglass_block@0"
            ]
        },
        {
            "x": -2,
            "y": 5,
            "z": 3,
            "elements": [
                "engineersdecor:panzerglass_block@0"
            ]
        },
        {
            "x": -2,
            "y": 5,
            "z": 2,
            "elements": [
                "engineersdecor:panzerglass_block@0"
            ]
        },
        {
            "x": 0,
            "y": 5,
            "z": 0,
            "elements": [
                "engineersdecor:panzerglass_block@0"
            ]
        },
        {
            "x": 0,
            "y": 5,
            "z": 1,
            "elements": [
                "contenttweaker:crystal_metal_block@0"
            ]
        },
        {
            "x": 1,
            "y": 4,
            "z": 0,
            "elements": [
                "engineersdecor:panzerglass_block@0"
            ]
        },
        {
            "x": -2,
            "y": 2,
            "z": 2,
            "elements": [
                "engineersdecor:panzerglass_block@0"
            ]
        },
        {
            "x": -2,
            "y": 2,
            "z": 1,
            "elements": [
                "engineersdecor:panzerglass_block@0"
            ]
        },
        {
            "x": 2,
            "y": 0,
            "z": 2,
            "elements": [
                "casings_all",
                "modularmachinery:blockwillproviderinput@0",
                "modularmachinery:blockgridproviderinput@0",
                "modularmachinery:blockmanainputhatch@0",
                
                
                "modularmachinery:blocklifeessenceproviderinput@0"
            ]
        },
        {
            "x": 1,
            "y": 4,
            "z": 4,
            "elements": [
                "engineersdecor:panzerglass_block@0"
            ]
        },
        {
            "x": 2,
            "y": 0,
            "z": 1,
            "elements": [
                "casings_all",
                "modularmachinery:blockwillproviderinput@0",
                "modularmachinery:blockgridproviderinput@0",
                "modularmachinery:blockmanainputhatch@0",
                
                
                "modularmachinery:blocklifeessenceproviderinput@0"
            ]
        },
        {
            "x": -2,
            "y": 2,
            "z": 3,
            "elements": [
                "engineersdecor:panzerglass_block@0"
            ]
        },
        {
            "x": 2,
            "y": 0,
            "z": 3,
            "elements": [
                "casings_all",
                "modularmachinery:blockwillproviderinput@0",
                "modularmachinery:blockgridproviderinput@0",
                "modularmachinery:blockmanainputhatch@0",
                
                
                "modularmachinery:blocklifeessenceproviderinput@0"
            ]
        },
        {
            "x": 1,
            "y": 0,
            "z": 4,
            "elements": [
                "casings_all",
                "modularmachinery:blockwillproviderinput@0",
                "modularmachinery:blockgridproviderinput@0",
                "modularmachinery:blockmanainputhatch@0",
                
                
                "modularmachinery:blocklifeessenceproviderinput@0"
            ]
        },
        {
            "x": 1,
            "y": 0,
            "z": 3,
            "elements": [
                "casings_all",
                "modularmachinery:blockwillproviderinput@0",
                "modularmachinery:blockgridproviderinput@0",
                "modularmachinery:blockmanainputhatch@0",
                
                
                "modularmachinery:blocklifeessenceproviderinput@0"
            ]
        },
        {
            "x": 1,
            "y": 0,
            "z": 2,
            "elements": [
                "casings_all",
                "modularmachinery:blockwillproviderinput@0",
                "modularmachinery:blockgridproviderinput@0",
                "modularmachinery:blockmanainputhatch@0",
                
                
                "modularmachinery:blocklifeessenceproviderinput@0"
            ]
        },
        {
            "x": 1,
            "y": 0,
            "z": 1,
            "elements": [
                "casings_all",
                "modularmachinery:blockwillproviderinput@0",
                "modularmachinery:blockgridproviderinput@0",
                "modularmachinery:blockmanainputhatch@0",
                
                
                "modularmachinery:blocklifeessenceproviderinput@0"
            ]
        },
        {
            "x": 1,
            "y": 0,
            "z": 0,
            "elements": [
                "casings_all",
                "modularmachinery:blockwillproviderinput@0",
                "modularmachinery:blockgridproviderinput@0",
                "modularmachinery:blockmanainputhatch@0",
                
                
                "modularmachinery:blocklifeessenceproviderinput@0"
            ]
        },
        {
            "x": -2,
            "y": 6,
            "z": 3,
            "elements": [
                "casings_all",
                "modularmachinery:blockwillproviderinput@0",
                "modularmachinery:blockgridproviderinput@0",
                "modularmachinery:blockmanainputhatch@0",
                
                
                "modularmachinery:blocklifeessenceproviderinput@0"
            ]
        },
        {
            "x": -1,
            "y": 1,
            "z": 4,
            "elements": [
                "engineersdecor:panzerglass_block@0"
            ]
        },
        {
            "x": -1,
            "y": 1,
            "z": 2,
            "elements": [
                "contenttweaker:crystal_metal_block@0"
            ]
        },
        {
            "x": -1,
            "y": 1,
            "z": 0,
            "elements": [
                "engineersdecor:panzerglass_block@0"
            ]
        },
        {
            "x": -1,
            "y": 4,
            "z": 0,
            "elements": [
                "engineersdecor:panzerglass_block@0"
            ]
        },
        {
            "x": 0,
            "y": 2,
            "z": 2,
            "elements": [
                "contenttweaker:rotor@0"
            ]
        },
        {
            "x": -2,
            "y": 3,
            "z": 3,
            "elements": [
                "engineersdecor:panzerglass_block@0"
            ]
        },
        {
            "x": 2,
            "y": 1,
            "z": 1,
            "elements": [
                "engineersdecor:panzerglass_block@0"
            ]
        },
        {
            "x": -2,
            "y": 3,
            "z": 2,
            "elements": [
                "engineersdecor:panzerglass_block@0"
            ]
        },
        {
            "x": 2,
            "y": 1,
            "z": 2,
            "elements": [
                "engineersdecor:panzerglass_block@0"
            ]
        },
        {
            "x": 0,
            "y": 2,
            "z": 4,
            "elements": [
                "engineersdecor:panzerglass_block@0"
            ]
        },
        {
            "x": 2,
            "y": 1,
            "z": 3,
            "elements": [
                "engineersdecor:panzerglass_block@0"
            ]
        },
        {
            "x": 1,
            "y": 3,
            "z": 4,
            "elements": [
                "engineersdecor:panzerglass_block@0"
            ]
        },
        {
            "x": -1,
            "y": 4,
            "z": 4,
            "elements": [
                "engineersdecor:panzerglass_block@0"
            ]
        },
        {
            "x": -2,
            "y": 3,
            "z": 1,
            "elements": [
                "engineersdecor:panzerglass_block@0"
            ]
        },
        {
            "x": 0,
            "y": 2,
            "z": 0,
            "elements": [
                "engineersdecor:panzerglass_block@0"
            ]
        },
        {
            "x": -2,
            "y": 0,
            "z": 3,
            "elements": [
                "casings_all",
                "modularmachinery:blockwillproviderinput@0",
                "modularmachinery:blockgridproviderinput@0",
                "modularmachinery:blockmanainputhatch@0",
                
                
                "modularmachinery:blocklifeessenceproviderinput@0"
            ]
        },
        {
            "x": -2,
            "y": 0,
            "z": 1,
            "elements": [
                "casings_all",
                "modularmachinery:blockwillproviderinput@0",
                "modularmachinery:blockgridproviderinput@0",
                "modularmachinery:blockmanainputhatch@0",
                
                
                "modularmachinery:blocklifeessenceproviderinput@0"
            ]
        },
        {
            "x": -2,
            "y": 0,
            "z": 2,
            "elements": [
                "casings_all",
                "modularmachinery:blockwillproviderinput@0",
                "modularmachinery:blockgridproviderinput@0",
                "modularmachinery:blockmanainputhatch@0",
                
                
                "modularmachinery:blocklifeessenceproviderinput@0"
            ]
        },
        {
            "x": 1,
            "y": 3,
            "z": 2,
            "elements": [
                "contenttweaker:crystal_metal_block@0"
            ]
        },
        {
            "x": 2,
            "y": 5,
            "z": 1,
            "elements": [
                "engineersdecor:panzerglass_block@0"
            ]
        },
        {
            "x": 2,
            "y": 5,
            "z": 2,
            "elements": [
                "engineersdecor:panzerglass_block@0"
            ]
        },
        {
            "x": 2,
            "y": 5,
            "z": 3,
            "elements": [
                "engineersdecor:panzerglass_block@0"
            ]
        },
        {
            "x": 1,
            "y": 3,
            "z": 0,
            "elements": [
                "engineersdecor:panzerglass_block@0"
            ]
        },
        {
            "x": 0,
            "y": 6,
            "z": 0,
            "elements": [
                "casings_all",
                "modularmachinery:blockwillproviderinput@0",
                "modularmachinery:blockgridproviderinput@0",
                "modularmachinery:blockmanainputhatch@0",
                
                
                "modularmachinery:blocklifeessenceproviderinput@0"
            ]
        },
        {
            "x": 1,
            "y": 6,
            "z": 4,
            "elements": [
                "casings_all",
                "modularmachinery:blockwillproviderinput@0",
                "modularmachinery:blockgridproviderinput@0",
                "modularmachinery:blockmanainputhatch@0",
                
                
                "modularmachinery:blocklifeessenceproviderinput@0"
            ]
        },
        {
            "x": 0,
            "y": 6,
            "z": 1,
            "elements": [
                "casings_all",
                "modularmachinery:blockwillproviderinput@0",
                "modularmachinery:blockgridproviderinput@0",
                "modularmachinery:blockmanainputhatch@0",
                
                
                "modularmachinery:blocklifeessenceproviderinput@0"
            ]
        },
        {
            "x": 1,
            "y": 6,
            "z": 2,
            "elements": [
                "casings_all",
                "modularmachinery:blockwillproviderinput@0",
                "modularmachinery:blockgridproviderinput@0",
                "modularmachinery:blockmanainputhatch@0",
                
                
                "modularmachinery:blocklifeessenceproviderinput@0"
            ]
        },
        {
            "x": 0,
            "y": 6,
            "z": 2,
            "elements": [
                "casings_all",
                "modularmachinery:blockwillproviderinput@0",
                "modularmachinery:blockgridproviderinput@0",
                "modularmachinery:blockmanainputhatch@0",
                
                
                "modularmachinery:blocklifeessenceproviderinput@0"
            ]
        },
        {
            "x": 1,
            "y": 6,
            "z": 3,
            "elements": [
                "casings_all",
                "modularmachinery:blockwillproviderinput@0",
                "modularmachinery:blockgridproviderinput@0",
                "modularmachinery:blockmanainputhatch@0",
                
                
                "modularmachinery:blocklifeessenceproviderinput@0"
            ]
        },
        {
            "x": 2,
            "y": 2,
            "z": 1,
            "elements": [
                "engineersdecor:panzerglass_block@0"
            ]
        },
        {
            "x": 1,
            "y": 6,
            "z": 0,
            "elements": [
                "casings_all",
                "modularmachinery:blockwillproviderinput@0",
                "modularmachinery:blockgridproviderinput@0",
                "modularmachinery:blockmanainputhatch@0",
                
                
                "modularmachinery:blocklifeessenceproviderinput@0"
            ]
        },
        {
            "x": 0,
            "y": 6,
            "z": 3,
            "elements": [
                "casings_all",
                "modularmachinery:blockwillproviderinput@0",
                "modularmachinery:blockgridproviderinput@0",
                "modularmachinery:blockmanainputhatch@0",
                
                
                "modularmachinery:blocklifeessenceproviderinput@0"
            ]
        },
        {
            "x": 2,
            "y": 2,
            "z": 2,
            "elements": [
                "engineersdecor:panzerglass_block@0"
            ]
        },
        {
            "x": 1,
            "y": 6,
            "z": 1,
            "elements": [
                "casings_all",
                "modularmachinery:blockwillproviderinput@0",
                "modularmachinery:blockgridproviderinput@0",
                "modularmachinery:blockmanainputhatch@0",
                
                
                "modularmachinery:blocklifeessenceproviderinput@0"
            ]
        },
        {
            "x": 0,
            "y": 6,
            "z": 4,
            "elements": [
                "casings_all",
                "modularmachinery:blockwillproviderinput@0",
                "modularmachinery:blockgridproviderinput@0",
                "modularmachinery:blockmanainputhatch@0",
                
                
                "modularmachinery:blocklifeessenceproviderinput@0"
            ]
        },
        {
            "x": -1,
            "y": 0,
            "z": 3,
            "elements": [
                "casings_all",
                "modularmachinery:blockwillproviderinput@0",
                "modularmachinery:blockgridproviderinput@0",
                "modularmachinery:blockmanainputhatch@0",
                
                
                "modularmachinery:blocklifeessenceproviderinput@0"
            ]
        },
        {
            "x": -1,
            "y": 5,
            "z": 2,
            "elements": [
                "contenttweaker:crystal_metal_block@0"
            ]
        },
        {
            "x": -1,
            "y": 0,
            "z": 2,
            "elements": [
                "casings_all",
                "modularmachinery:blockwillproviderinput@0",
                "modularmachinery:blockgridproviderinput@0",
                "modularmachinery:blockmanainputhatch@0",
                
                
                "modularmachinery:blocklifeessenceproviderinput@0"
            ]
        },
        {
            "x": -1,
            "y": 0,
            "z": 1,
            "elements": [
                "casings_all",
                "modularmachinery:blockwillproviderinput@0",
                "modularmachinery:blockgridproviderinput@0",
                "modularmachinery:blockmanainputhatch@0",
                
                
                "modularmachinery:blocklifeessenceproviderinput@0"
            ]
        },
        {
            "x": -1,
            "y": 5,
            "z": 0,
            "elements": [
                "engineersdecor:panzerglass_block@0"
            ]
        },
        {
            "x": -1,
            "y": 0,
            "z": 0,
            "elements": [
                "casings_all",
                "modularmachinery:blockwillproviderinput@0",
                "modularmachinery:blockgridproviderinput@0",
                "modularmachinery:blockmanainputhatch@0",
                
                
                "modularmachinery:blocklifeessenceproviderinput@0"
            ]
        },
        {
            "x": -1,
            "y": 0,
            "z": 4,
            "elements": [
                "casings_all",
                "modularmachinery:blockwillproviderinput@0",
                "modularmachinery:blockgridproviderinput@0",
                "modularmachinery:blockmanainputhatch@0",
                
                
                "modularmachinery:blocklifeessenceproviderinput@0"
            ]
        },
        {
            "x": 2,
            "y": 2,
            "z": 3,
            "elements": [
                "engineersdecor:panzerglass_block@0"
            ]
        },
        {
            "x": 2,
            "y": 4,
            "z": 1,
            "elements": [
                "engineersdecor:panzerglass_block@0"
            ]
        },
        {
            "x": 2,
            "y": 4,
            "z": 2,
            "elements": [
                "engineersdecor:panzerglass_block@0"
            ]
        },
        {
            "x": 2,
            "y": 4,
            "z": 3,
            "elements": [
                "engineersdecor:panzerglass_block@0"
            ]
        },
        {
            "x": -1,
            "y": 2,
            "z": 0,
            "elements": [
                "engineersdecor:panzerglass_block@0"
            ]
        },
        {
            "x": 0,
            "y": 4,
            "z": 4,
            "elements": [
                "engineersdecor:panzerglass_block@0"
            ]
        },
        {
            "x": -1,
            "y": 2,
            "z": 4,
            "elements": [
                "engineersdecor:panzerglass_block@0"
            ]
        },
        {
            "x": -2,
            "y": 6,
            "z": 2,
            "elements": [
                "casings_all",
                "modularmachinery:blockwillproviderinput@0",
                "modularmachinery:blockgridproviderinput@0",
                "modularmachinery:blockmanainputhatch@0",
                
                
                "modularmachinery:blocklifeessenceproviderinput@0"
            ]
        },
        {
            "x": -2,
            "y": 6,
            "z": 1,
            "elements": [
                "casings_all",
                "modularmachinery:blockwillproviderinput@0",
                "modularmachinery:blockgridproviderinput@0",
                "modularmachinery:blockmanainputhatch@0",
                
                
                "modularmachinery:blocklifeessenceproviderinput@0"
            ]
        },
        {
            "x": 0,
            "y": 1,
            "z": 1,
            "elements": [
                "contenttweaker:crystal_metal_block@0"
            ]
        },
        {
            "x": 0,
            "y": 1,
            "z": 0,
            "elements": [
                "engineersdecor:panzerglass_block@0"
            ]
        },
        {
            "x": 0,
            "y": 1,
            "z": 3,
            "elements": [
                "contenttweaker:crystal_metal_block@0"
            ]
        },
        {
            "x": 0,
            "y": 1,
            "z": 2,
            "elements": [
                "contenttweaker:rotor@0"
            ]
        },
        {
            "x": -1,
            "y": 5,
            "z": 4,
            "elements": [
                "engineersdecor:panzerglass_block@0"
            ]
        },
        {
            "x": 0,
            "y": 1,
            "z": 4,
            "elements": [
                "engineersdecor:panzerglass_block@0"
            ]
        }
    ]}