{
    "registryname": "tree_powered_compressor",
    "localizedname": "Tree powered compressor",
    "color": "41414a",
    "modifiers": [
        {"description": "x4 speed",
            "x": -1,
            "y": 1,
            "z": 1,
            "elements": [
                "contenttweaker:slimy_glass@0"
            ],
            "modifier": [
                {
                    "io": "input",
                    "target": "duration",
                    "operation": 1,
                    "multiplier": 0.7937
                }
            ]
        },
        {
            "x": -1,
            "y": 1,
            "z": 0,
            "elements": [
                "contenttweaker:slimy_glass@0"
            ],
            "modifier": [
                {
                    "io": "input",
                    "target": "duration",
                    "operation": 1,
                    "multiplier": 0.7937
                }
            ]
        },
        {
            "x": -1,
            "y": 2,
            "z": 1,
            "elements": [
                "contenttweaker:slimy_glass@0"
            ],
            "modifier": [
                {
                    "io": "input",
                    "target": "duration",
                    "operation": 1,
                    "multiplier": 0.7937
                }
            ]
        },
        {
            "x": 1,
            "y": 1,
            "z": 0,
            "elements": [
                "contenttweaker:slimy_glass@0"
            ],
            "modifier": [
                {
                    "io": "input",
                    "target": "duration",
                    "operation": 1,
                    "multiplier": 0.7937
                }
            ]
        },
        {
            "x": -1,
            "y": 2,
            "z": 0,
            "elements": [
                "contenttweaker:slimy_glass@0"
            ],
            "modifier": [
                {
                    "io": "input",
                    "target": "duration",
                    "operation": 1,
                    "multiplier": 0.7937
                }
            ]
        },
        {
            "x": 1,
            "y": 2,
            "z": 1,
            "elements": [
                "contenttweaker:slimy_glass@0"
            ],
            "modifier": [
                {
                    "io": "input",
                    "target": "duration",
                    "operation": 1,
                    "multiplier": 0.7937
                }
            ]
        },
        {
            "x": 1,
            "y": 2,
            "z": 0,
            "elements": [
                "contenttweaker:slimy_glass@0"
            ],
            "modifier": [
                {
                    "io": "input",
                    "target": "duration",
                    "operation": 1,
                    "multiplier": 0.7937
                }
            ]
        },
        {
            "x": 0,
            "y": 1,
            "z": 0,
            "elements": [
                "contenttweaker:slimy_glass@0"
            ],
            "modifier": [
                {
                    "io": "input",
                    "target": "duration",
                    "operation": 1,
                    "multiplier": 0.7937
                }
            ]
        },
        {
            "x": 0,
            "y": 2,
            "z": 0,
            "elements": [
                "contenttweaker:slimy_glass@0"
            ],
            "modifier": [
                {
                    "io": "input",
                    "target": "duration",
                    "operation": 1,
                    "multiplier": 0.7937
                }
            ]
        },
        {
            "x": 1,
            "y": 1,
            "z": 1,
            "elements": [
                "contenttweaker:slimy_glass@0"
            ],
            "modifier": [
                {
                    "io": "input",
                    "target": "duration",
                    "operation": 1,
                    "multiplier": 0.7937
                }
            ]
        }
    ],
    "parts": [
        {
            "x": -1,
            "y": 0,
            "z": 2,
            
            "elements": [
                "casings_all"
            ]
        },
        {
            "x": -1,
            "y": 0,
            "z": 1,
            
            "elements": [
                "casings_all"
            ]
        },
        {
            "x": 1,
            "y": 0,
            "z": 2,
            
            "elements": [
                "casings_all"
            ]
        },
        {
            "x": -1,
            "y": 0,
            "z": 0,
            
            "elements": [
                "casings_all"
            ]
        },
        {
            "x": 1,
            "y": 0,
            "z": 1,
            
            "elements": [
                "casings_all"
            ]
        },
        {
            "x": 0,
            "y": 3,
            "z": 1,
            "elements": [
                "thermalfoundation:storage_alloy@3"
            ]
        },
        {
            "x": 0,
            "y": 3,
            "z": 0,
            "elements": [
                "roots:runestone_slab@0"
            ]
        },
        {
            "x": 1,
            "y": 0,
            "z": 0,
            
            "elements": [
                "casings_all"
            ]
        },
        {
            "x": 0,
            "y": 3,
            "z": 2,
            "elements": [
                "roots:runestone_slab@0"
            ]
        },
        {
            "x": 1,
            "y": 1,
            "z": 0,
            "elements": [
                "chisel:glass@9"
            ]
        },
        {
            "x": 1,
            "y": 1,
            "z": 2,
            "elements": [
                "roots:runestone@0"
            ]
        },
        {
            "x": 1,
            "y": 1,
            "z": 1,
            "elements": [
                "chisel:glass@9"
            ]
        },
        {
            "x": -1,
            "y": 1,
            "z": 2,
            "elements": [
                "roots:runestone@0"
            ]
        },
        {
            "x": -1,
            "y": 1,
            "z": 1,
            "elements": [
                "chisel:glass@9"
            ]
        },
        {
            "x": -1,
            "y": 4,
            "z": 2,
            "elements": [
                "roots:runestone_wall@0"
            ]
        },
        {
            "x": -1,
            "y": 1,
            "z": 0,
            "elements": [
                "chisel:glass@9"
            ]
        },
        {
            "x": -1,
            "y": 4,
            "z": 0,
            "elements": [
                "roots:runestone_wall@0"
            ]
        },
        {
            "x": 0,
            "y": 2,
            "z": 2,
            "elements": [
                "roots:runestone@0"
            ]
        },
        {
            "x": 0,
            "y": 2,
            "z": 1,
            "elements": [
                "minecraft:sapling@0"
            ]
        },
        {
            "x": 0,
            "y": 2,
            "z": 0,
            "elements": [
                "chisel:glass@9"
            ]
        },
        {
            "x": 1,
            "y": 3,
            "z": 1,
            "elements": [
                "roots:runestone_slab@0"
            ]
        },
        {
            "x": 1,
            "y": 3,
            "z": 2,
            "elements": [
                "roots:runestone@0"
            ]
        },
        {
            "x": 0,
            "y": 0,
            "z": 2,
            
            "elements": [
                "casings_all"
            ]
        },
        {
            "x": 0,
            "y": 0,
            "z": 1,
            "elements": [
                "thermalfoundation:storage_alloy@3"
            ]
        },
        {
            "x": 1,
            "y": 3,
            "z": 0,
            "elements": [
                "roots:runestone@0"
            ]
        },
        {
            "x": -1,
            "y": 2,
            "z": 1,
            "elements": [
                "chisel:glass@9"
            ]
        },
        {
            "x": -1,
            "y": 2,
            "z": 0,
            "elements": [
                "chisel:glass@9"
            ]
        },
        {
            "x": 1,
            "y": 2,
            "z": 2,
            "elements": [
                "roots:runestone@0"
            ]
        },
        {
            "x": -1,
            "y": 3,
            "z": 2,
            "elements": [
                "roots:runestone@0"
            ]
        },
        {
            "x": 1,
            "y": 2,
            "z": 1,
            "elements": [
                "chisel:glass@9"
            ]
        },
        {
            "x": 1,
            "y": 2,
            "z": 0,
            "elements": [
                "chisel:glass@9"
            ]
        },
        {
            "x": -1,
            "y": 3,
            "z": 1,
            "elements": [
                "roots:runestone_slab@0"
            ]
        },
        {
            "x": -1,
            "y": 3,
            "z": 0,
            "elements": [
                "roots:runestone@0"
            ]
        },
        {
            "x": -1,
            "y": 2,
            "z": 2,
            "elements": [
                "roots:runestone@0"
            ]
        },
        {
            "x": 1,
            "y": 4,
            "z": 0,
            "elements": [
                "roots:runestone_wall@0"
            ]
        },
        {
            "x": 0,
            "y": 1,
            "z": 1,
            "elements": [
                "minecraft:grass@0"
            ]
        },
        {
            "x": 0,
            "y": 1,
            "z": 0,
            "elements": [
                "chisel:glass@9"
            ]
        },
        {
            "x": 0,
            "y": 1,
            "z": 2,
            "elements": [
                "roots:runestone@0"
            ]
        },
        {
            "x": 1,
            "y": 4,
            "z": 2,
            "elements": [
                "roots:runestone_wall@0"
            ]
        }
    ]}